<?xml version="1.0"?>
<robot xmlns:xacro="http://www.ros.org/wiki/xacro" name="planar_rrr_robot">
  <xacro:property name="l1" value="1.0"/>
  <xacro:property name="l2" value="1.0"/>
  <xacro:property name="l3" value="1.0"/>
  <link name="base_link">
    <visual>
      <geometry>
        <cylinder length="0.1" radius="0.1"/>
      </geometry>
    </visual>
    <collision>
      <geometry>
        <cylinder length="0.1" radius="0.1"/>
      </geometry>
    </collision>
  </link>
  <joint name="joint1" type="continuous">
    <parent link="base_link"/>
    <child link="link1"/>
    <origin xyz="0 0 0" rpy="0 0 0"/>
    <axis xyz="1 0 0"/>
  </joint>
  <link name="link1">
    <visual>
      <geometry>
        <box size="0.1 0.1 ${l1}"/>
      </geometry>
      <origin xyz="0 0 ${l1/2}" rpy="0 0 0"/>
    </visual>
    <collision>
      <geometry>
        <box size="0.1 0.1 ${l1}"/>
      </geometry>
      <origin xyz="0 0 ${l1/2}" rpy="0 0 0"/>
    </collision>
  </link>
  <joint name="joint2" type="continuous">
    <parent link="link1"/>
    <child link="link2"/>
    <origin xyz="0 0 ${l1}" rpy="0 0 0"/>
    <axis xyz="1 0 0"/>
  </joint>
  <link name="link2">
    <visual>
      <geometry>
        <box size="0.1 0.1 ${l2}"/>
      </geometry>
      <origin xyz="0 0 ${l2/2}" rpy="0 0 0"/>
    </visual>
    <collision>
      <geometry>
        <box size="0.1 0.1 ${l2}"/>
      </geometry>
      <origin xyz="0 0 ${l2/2}" rpy="0 0 0"/>
    </collision>
  </link>
  <joint name="joint3" type="continuous">
    <parent link="link2"/>
    <child link="link3"/>
    <origin xyz="0 0 ${l2}" rpy="0 0 0"/>
    <axis xyz="1 0 0"/>
  </joint>
  <link name="link3">
    <visual>
      <geometry>
        <box size="0.1 0.1 ${l3}"/>
      </geometry>
      <origin xyz="0 0 ${l3/2}" rpy="0 0 0"/>
    </visual>
    <collision>
      <geometry>
        <box size="0.1 0.1 ${l3}"/>
      </geometry>
      <origin xyz="0 0 ${l3/2}" rpy="0 0 0"/>
    </collision>
  </link>
  <joint name="end_effector_joint" type="fixed">
    <parent link="link3"/>
    <child link="end_effector"/>
    <origin xyz="0 0 ${l3}" rpy="0 0 0"/>
  </joint>
  <link name="end_effector"/>
</robot>
